[2025-10-20T10:07:27.469+0000] {taskinstance.py:1165} INFO - Dependencies all met for <TaskInstance: ethiopia_flexible_download.download_ethiopia_data manual__2025-10-20T15:37:15+05:30 [queued]>
[2025-10-20T10:07:27.481+0000] {taskinstance.py:1165} INFO - Dependencies all met for <TaskInstance: ethiopia_flexible_download.download_ethiopia_data manual__2025-10-20T15:37:15+05:30 [queued]>
[2025-10-20T10:07:27.482+0000] {taskinstance.py:1362} INFO - 
--------------------------------------------------------------------------------
[2025-10-20T10:07:27.482+0000] {taskinstance.py:1363} INFO - Starting attempt 1 of 2
[2025-10-20T10:07:27.483+0000] {taskinstance.py:1364} INFO - 
--------------------------------------------------------------------------------
[2025-10-20T10:07:27.497+0000] {taskinstance.py:1383} INFO - Executing <Task(PythonOperator): download_ethiopia_data> on 2025-10-20 10:07:15+00:00
[2025-10-20T10:07:27.504+0000] {standard_task_runner.py:55} INFO - Started process 872 to run task
[2025-10-20T10:07:27.508+0000] {standard_task_runner.py:82} INFO - Running: ['***', 'tasks', 'run', 'ethiopia_flexible_download', 'download_ethiopia_data', 'manual__2025-10-20T15:37:15+05:30', '--job-id', '22', '--raw', '--subdir', 'DAGS_FOLDER/ethiopia_flexible_download.py', '--cfg-path', '/tmp/tmpevoy4m4g']
[2025-10-20T10:07:27.513+0000] {standard_task_runner.py:83} INFO - Job 22: Subtask download_ethiopia_data
[2025-10-20T10:07:27.610+0000] {task_command.py:376} INFO - Running <TaskInstance: ethiopia_flexible_download.download_ethiopia_data manual__2025-10-20T15:37:15+05:30 [running]> on host da48842a6a56
[2025-10-20T10:07:27.696+0000] {taskinstance.py:1592} INFO - Exporting the following env vars:
AIRFLOW_CTX_DAG_OWNER=ethiopia_project
AIRFLOW_CTX_DAG_ID=ethiopia_flexible_download
AIRFLOW_CTX_TASK_ID=download_ethiopia_data
AIRFLOW_CTX_EXECUTION_DATE=2025-10-20T10:07:15+00:00
AIRFLOW_CTX_TRY_NUMBER=1
AIRFLOW_CTX_DAG_RUN_ID=manual__2025-10-20T15:37:15+05:30
[2025-10-20T10:07:27.699+0000] {taskinstance.py:1851} ERROR - Task failed with exception
Traceback (most recent call last):
  File "/home/airflow/.local/lib/python3.7/site-packages/airflow/operators/python.py", line 175, in execute
    return_value = self.execute_callable()
  File "/home/airflow/.local/lib/python3.7/site-packages/airflow/operators/python.py", line 193, in execute_callable
    return self.python_callable(*self.op_args, **self.op_kwargs)
  File "/opt/airflow/dags/ethiopia_flexible_download.py", line 51, in process_ethiopia_data
    print(f"Processing {year}-{month_selection:02d}")
ValueError: Unknown format code 'd' for object of type 'str'
[2025-10-20T10:07:27.711+0000] {taskinstance.py:1406} INFO - Marking task as UP_FOR_RETRY. dag_id=ethiopia_flexible_download, task_id=download_ethiopia_data, execution_date=20251020T100715, start_date=20251020T100727, end_date=20251020T100727
[2025-10-20T10:07:27.725+0000] {standard_task_runner.py:105} ERROR - Failed to execute job 22 for task download_ethiopia_data (Unknown format code 'd' for object of type 'str'; 872)
[2025-10-20T10:07:27.761+0000] {local_task_job.py:164} INFO - Task exited with return code 1
[2025-10-20T10:07:27.804+0000] {local_task_job.py:273} INFO - 0 downstream tasks scheduled from follow-on schedule check
