[2025-10-20T11:44:20.340+0000] {taskinstance.py:1165} INFO - Dependencies all met for <TaskInstance: ethiopia_flexible_download.download_ethiopia_data manual__2025-10-20T17:12:08+05:30 [queued]>
[2025-10-20T11:44:20.355+0000] {taskinstance.py:1165} INFO - Dependencies all met for <TaskInstance: ethiopia_flexible_download.download_ethiopia_data manual__2025-10-20T17:12:08+05:30 [queued]>
[2025-10-20T11:44:20.355+0000] {taskinstance.py:1362} INFO - 
--------------------------------------------------------------------------------
[2025-10-20T11:44:20.357+0000] {taskinstance.py:1363} INFO - Starting attempt 2 of 2
[2025-10-20T11:44:20.357+0000] {taskinstance.py:1364} INFO - 
--------------------------------------------------------------------------------
[2025-10-20T11:44:20.378+0000] {taskinstance.py:1383} INFO - Executing <Task(PythonOperator): download_ethiopia_data> on 2025-10-20 11:42:08+00:00
[2025-10-20T11:44:20.388+0000] {standard_task_runner.py:55} INFO - Started process 5495 to run task
[2025-10-20T11:44:20.392+0000] {standard_task_runner.py:82} INFO - Running: ['***', 'tasks', 'run', 'ethiopia_flexible_download', 'download_ethiopia_data', 'manual__2025-10-20T17:12:08+05:30', '--job-id', '31', '--raw', '--subdir', 'DAGS_FOLDER/ethiopia_flexible_download.py', '--cfg-path', '/tmp/tmpcv_dp7wy']
[2025-10-20T11:44:20.395+0000] {standard_task_runner.py:83} INFO - Job 31: Subtask download_ethiopia_data
[2025-10-20T11:44:20.487+0000] {task_command.py:376} INFO - Running <TaskInstance: ethiopia_flexible_download.download_ethiopia_data manual__2025-10-20T17:12:08+05:30 [running]> on host da48842a6a56
[2025-10-20T11:44:20.645+0000] {taskinstance.py:1592} INFO - Exporting the following env vars:
AIRFLOW_CTX_DAG_OWNER=ethiopia_project
AIRFLOW_CTX_DAG_ID=ethiopia_flexible_download
AIRFLOW_CTX_TASK_ID=download_ethiopia_data
AIRFLOW_CTX_EXECUTION_DATE=2025-10-20T11:42:08+00:00
AIRFLOW_CTX_TRY_NUMBER=2
AIRFLOW_CTX_DAG_RUN_ID=manual__2025-10-20T17:12:08+05:30
[2025-10-20T11:44:20.653+0000] {taskinstance.py:1851} ERROR - Task failed with exception
Traceback (most recent call last):
  File "/home/airflow/.local/lib/python3.7/site-packages/airflow/operators/python.py", line 175, in execute
    return_value = self.execute_callable()
  File "/home/airflow/.local/lib/python3.7/site-packages/airflow/operators/python.py", line 193, in execute_callable
    return self.python_callable(*self.op_args, **self.op_kwargs)
  File "/opt/airflow/dags/ethiopia_flexible_download.py", line 52, in process_ethiopia_data
    raise ValueError(f"Invalid month: {month_num}. Must be 1-12 or 'all'")
ValueError: Invalid month: 14. Must be 1-12 or 'all'
[2025-10-20T11:44:20.682+0000] {taskinstance.py:1406} INFO - Marking task as FAILED. dag_id=ethiopia_flexible_download, task_id=download_ethiopia_data, execution_date=20251020T114208, start_date=20251020T114420, end_date=20251020T114420
[2025-10-20T11:44:20.713+0000] {standard_task_runner.py:105} ERROR - Failed to execute job 31 for task download_ethiopia_data (Invalid month: 14. Must be 1-12 or 'all'; 5495)
[2025-10-20T11:44:20.780+0000] {local_task_job.py:164} INFO - Task exited with return code 1
[2025-10-20T11:44:20.814+0000] {local_task_job.py:273} INFO - 0 downstream tasks scheduled from follow-on schedule check
